<?xml version = "1.0"?>
<!-- Create a robot model --> 
<robot name = "bot">
    <!-- Create Link -->

    <!-- Robot Footprint: 用于计算机器人运动时的地面坐标 -->
    <link name = "base_footprint" />

    <!-- Base Link: 机器人物理意义上的原点 -->
    <link name = "base_link" >
        <visual>
            <origin xyz = "0 0 0" rpy="0 0 0"/>
            <geometry>
                <cylinder length = "0.12" radius = "0.1"/>
            </geometry>    
            <material name = "blue"> 
                <color rgba = "0.1 0.1 1.0 0.5"/>
            </material>
        </visual>
    </link>

    <!-- laser link: 激光雷达 -->
    <link name="laser_link">
        <visual>
            <origin xyz="0 0 0" rpy="0 0 0"/>
            <geometry>
                <cylinder length="0.02" radius="0.02"/>
            </geometry>
            <material name="black">
                <color rgba="0.0 0.0 0.0 0.8" /> 
        </material>
        </visual>
    </link>

    <!-- imu link: IMU -->
    <link name="imu_link">
        <visual>
            <origin xyz="0 0 0" rpy="0 0 0"/>
            <geometry>
                <box size="0.02 0.02 0.02"/>
            </geometry>
        </visual>
    </link>

    <!-- left wheel link -->
    <link name="left_wheel_link">
        <visual>
            <origin xyz="0 0 0" rpy="1.57079 0 0"/>
            <geometry>
                <cylinder length="0.04" radius="0.032"/>
            </geometry>
            <material name="black">
                <color rgba="0.0 0.0 0.0 0.5" /> 
            </material>
        </visual>
    </link>

    <!-- right wheel link -->
    <link name="right_wheel_link">
        <visual>
            <origin xyz="0 0 0" rpy="1.57079 0 0"/>
            <geometry>
                <cylinder length="0.04" radius="0.032"/>
            </geometry>
            <material name="black">
                <color rgba="0.0 0.0 0.0 0.5" /> 
            </material>
        </visual>
    </link>

    <!-- caster link -->
    <link name="caster_link">
        <visual>
        <origin xyz="0 0 0" rpy="0 0 0"/>
        <geometry>
            <sphere radius="0.016"/>
        </geometry>
            <material name="black">
            <color rgba="0.0 0.0 0.0 0.5" /> 
            </material>
        </visual>
    </link>

    <!-- Create Joint -->
    
    <!-- laser joint -->
    <joint name="laser_joint" type="fixed">
        <parent link="base_link" />
        <child link="laser_link" />
        <origin xyz="0 0 0.075" />
    </joint>

    <!-- imu joint -->
    <joint name="imu_joint" type="fixed">
        <parent link="base_link" />
        <child link="imu_link" />
        <origin xyz="0 0 0.02" />
    </joint>

    <!-- left wheel joint -->
    <joint name="left_wheel_joint" type="continuous">
        <parent link="base_link" />
        <child link="left_wheel_link" />
        <origin xyz="-0.02 0.10 -0.06" />
        <axis xyz="0 1 0" />    
    </joint>

    <!-- right wheel joint -->
    <joint name="right_wheel_joint" type="continuous">
        <parent link="base_link" />
        <child link="right_wheel_link" />
        <origin xyz="-0.02 -0.10 -0.06" />
        <axis xyz="0 1 0" />    
    </joint>

    <!-- Caster joint -->
    <joint name="caster_joint" type="fixed">
        <parent link="base_link" />
        <child link="caster_link" />
        <origin xyz="0.06 0.0 -0.076" />
    </joint>

    <!-- footprint joint: 建立base_footprint和base_link间的关系（通常为垂直投影） -->
    <joint name="base_joint" type="fixed">
        <parent link="base_footprint"/>
        <child link="base_link"/>
        <origin xyz="0.0 0.0 0.076" rpy="0 0 0"/>
    </joint>
</robot>